<?xml version="1.0"?>
<robot xmlns:xacro="http://www.ros.org/wiki/xacro">
    
    <xacro:include filename="inertial_macros.xacro"/>

    <material name="white">
        <color rgba="1 1 1 1"/>
    </material>

    <material name="orange">
        <color rgba="1 0.3 0.1 1"/>
    </material>

    <material name="blue">
        <color rgba="0.2 0.2 1 1"/>
    </material>

    <material name="black">
        <color rgba="0 0 0 1"/>
    </material>

    <material name="red">
        <color rgba="1 0 0 1"/>
    </material>

    <!-- BASE LINK -->

    <link name="base_link">

    </link>

    <!-- CHASSIS LINK -->

    <joint name="chassis_joint" type="fixed">
        <parent link="base_link"/>
        <child link="chassis"/>
        <origin xyz="-0.09 0 0"/>
    </joint>

    <link name="chassis">
        <visual>
            <origin xyz="0.09 0 0.03" rpy="0 0 0"/>
            <geometry>
                <box size="0.18 0.08 0.06"/>
            </geometry>
            <material name="white"/>
        </visual>
        <collision>
            <origin xyz="0.09 0 0.03" rpy="0 0 0"/>
            <geometry>
                <box size="0.18 0.08 0.06"/>
            </geometry>
        </collision>
        <xacro:inertial_box mass="0.01" x="0.18" y="0.08" z="0.06">
            <origin xyz="0.09 0 0.03" rpy="0 0 0"/>
        </xacro:inertial_box>
    </link>

    <gazebo reference="chassis">
        <material>Gazebo/White</material>
    </gazebo>

    <!-- REAR LEFT WHEEL LINK -->

    <joint name="rear_left_wheel_joint" type="continuous">
        <parent link="chassis"/>
        <child link="rear_left_wheel"/>
        <origin xyz="0.04 0.05 0.01" rpy="-${pi/2} 0 0"/>
        <axis xyz="0 0 1"/>
    </joint>

    <link name="rear_left_wheel">
        <visual>
            <geometry>
                <cylinder radius="0.03" length="0.025"/>
            </geometry>
            <material name="blue"/>
        </visual>
        <collision>
            <geometry>
                <cylinder radius="0.03" length="0.025"/>
            </geometry>
        </collision>
        <xacro:inertial_cylinder mass="0.01" length="0.025" radius="0.03">
            <origin xyz="0 0 0" rpy="0 0 0"/>
        </xacro:inertial_cylinder>
    </link>

    <gazebo reference="rear_left_wheel">
        <material>Gazebo/Blue</material>
    </gazebo>

    <!-- FRONT LEFT WHEEL LINK -->

    <joint name="front_left_wheel_joint" type="continuous">
        <parent link="chassis"/>
        <child link="front_left_wheel"/>
        <origin xyz="0.14 0.05 0.01" rpy="-${pi/2} 0 0"/>
        <axis xyz="0 0 1"/>
    </joint>

    <link name="front_left_wheel">
        <visual>
            <geometry>
                <cylinder radius="0.03" length="0.025"/>
            </geometry>
            <material name="blue"/>
        </visual>
        <collision>
            <geometry>
                <cylinder radius="0.03" length="0.025"/>
            </geometry>
        </collision>
        <xacro:inertial_cylinder mass="0.01" length="0.025" radius="0.03">
            <origin xyz="0 0 0" rpy="0 0 0"/>
        </xacro:inertial_cylinder>
    </link>

    <gazebo reference="front_left_wheel">
        <material>Gazebo/Blue</material>
    </gazebo>

    <!-- REAR RIGHT WHEEL LINK -->

    <joint name="rear_right_wheel_joint" type="continuous">
        <parent link="chassis"/>
        <child link="rear_right_wheel"/>
        <origin xyz="0.04 -0.05 0.01" rpy="${pi/2} 0 0"/>
        <axis xyz="0 0 -1"/>
    </joint>

    <link name="rear_right_wheel">
        <visual>
            <geometry>
                <cylinder radius="0.03" length="0.025"/>
            </geometry>
            <material name="blue"/>
        </visual>
        <collision>
            <geometry>
                <cylinder radius="0.03" length="0.025"/>
            </geometry>
        </collision>
        <xacro:inertial_cylinder mass="0.01" length="0.025" radius="0.03">
            <origin xyz="0 0 0" rpy="0 0 0"/>
        </xacro:inertial_cylinder>
    </link>

    <gazebo reference="rear_right_wheel">
        <material>Gazebo/Blue</material>
    </gazebo>

    <!-- FRONT RIGHT WHEEL LINK -->

    <joint name="front_right_wheel_joint" type="continuous">
        <parent link="chassis"/>
        <child link="front_right_wheel"/>
        <origin xyz="0.14 -0.05 0.01" rpy="${pi/2} 0 0"/>
        <axis xyz="0 0 -1"/>
    </joint>

    <link name="front_right_wheel">
        <visual>
            <geometry>
                <cylinder radius="0.03" length="0.025"/>
            </geometry>
            <material name="blue"/>
        </visual>
        <collision>
            <geometry>
                <cylinder radius="0.03" length="0.025"/>
            </geometry>
        </collision>
        <xacro:inertial_cylinder mass="0.01" length="0.025" radius="0.03">
            <origin xyz="0 0 0" rpy="0 0 0"/>
        </xacro:inertial_cylinder>
    </link>

    <gazebo reference="front_right_wheel">
        <material>Gazebo/Blue</material>
    </gazebo>

    <!-- FRONT CASTER WHEEL -->

    <!-- <joint name="caster_wheel_front_joint" type="fixed">
        <parent link="chassis"/>
        <child link="caster_wheel_front"/>
        <origin xyz="0.15 0 0.011" rpy="0 0 0"/>
    </joint>

    <link name="caster_wheel_front">
        <visual>
            <geometry>
                <sphere radius="0.03" />
            </geometry>
            <material name="black"/>
        </visual>
        <collision>
            <geometry>
                <sphere radius="0.03" />
            </geometry>
            <material name="black"/>
        </collision>
    </link>

    <gazebo reference="caster_wheel_front">
        <material>Gazebo/Black</material>
        <mu1 value="0..1"/>
        <mu1 value="0..1"/>
    </gazebo> -->
    
    <!-- REAR CASTER WHEEL -->

    <!-- <joint name="caster_wheel_rear_joint" type="fixed">
        <parent link="chassis"/>
        <child link="caster_wheel_rear"/>
        <origin xyz="0 0 0.011" rpy="0 0 0"/>
    </joint>

    <link name="caster_wheel_rear">
        <visual>
            <geometry>
                <sphere radius="0.03" />
            </geometry>
            <material name="black"/>
        </visual>
        <collision>
            <geometry>
                <sphere radius="0.03" />
            </geometry>
            <material name="black"/>
        </collision>
    </link>

    <gazebo reference="caster_wheel_rear">
        <material>Gazebo/Black</material>
    </gazebo> -->


</robot>
